[22/Feb/2020 07:16:12] DEBUG [/home/thanhtran/workspace/python/env/movie/lib/python3.5/site-packages/django/db/backends/base/schema.py:101] CREATE TABLE `django_migrations` (`id` integer AUTO_INCREMENT NOT NULL PRIMARY KEY, `app` varchar(255) NOT NULL, `name` varchar(255) NOT NULL, `applied` datetime(6) NOT NULL); (params None)
[22/Feb/2020 07:16:12] DEBUG [/home/thanhtran/workspace/python/env/movie/lib/python3.5/site-packages/django/db/backends/base/schema.py:101] CREATE TABLE `django_content_type` (`id` integer AUTO_INCREMENT NOT NULL PRIMARY KEY, `name` varchar(100) NOT NULL, `app_label` varchar(100) NOT NULL, `model` varchar(100) NOT NULL); (params None)
[22/Feb/2020 07:16:12] DEBUG [/home/thanhtran/workspace/python/env/movie/lib/python3.5/site-packages/django/db/backends/base/schema.py:101] ALTER TABLE `django_content_type` ADD CONSTRAINT `django_content_type_app_label_76bd3d3b_uniq` UNIQUE (`app_label`, `model`); (params [])
[22/Feb/2020 07:16:12] DEBUG [/home/thanhtran/workspace/python/env/movie/lib/python3.5/site-packages/django/db/backends/base/schema.py:101] ALTER TABLE `django_content_type` MODIFY `name` varchar(100) NULL; (params [])
[22/Feb/2020 07:16:12] DEBUG [/home/thanhtran/workspace/python/env/movie/lib/python3.5/site-packages/django/db/backends/base/schema.py:101] ALTER TABLE `django_content_type` DROP COLUMN `name` CASCADE; (params [])
[22/Feb/2020 07:16:12] DEBUG [/home/thanhtran/workspace/python/env/movie/lib/python3.5/site-packages/django/db/backends/base/schema.py:101] CREATE TABLE `auth_permission` (`id` integer AUTO_INCREMENT NOT NULL PRIMARY KEY, `name` varchar(50) NOT NULL, `content_type_id` integer NOT NULL, `codename` varchar(100) NOT NULL); (params None)
[22/Feb/2020 07:16:12] DEBUG [/home/thanhtran/workspace/python/env/movie/lib/python3.5/site-packages/django/db/backends/base/schema.py:101] CREATE TABLE `auth_group` (`id` integer AUTO_INCREMENT NOT NULL PRIMARY KEY, `name` varchar(80) NOT NULL UNIQUE); (params None)
[22/Feb/2020 07:16:12] DEBUG [/home/thanhtran/workspace/python/env/movie/lib/python3.5/site-packages/django/db/backends/base/schema.py:101] CREATE TABLE `auth_group_permissions` (`id` integer AUTO_INCREMENT NOT NULL PRIMARY KEY, `group_id` integer NOT NULL, `permission_id` integer NOT NULL); (params None)
[22/Feb/2020 07:16:12] DEBUG [/home/thanhtran/workspace/python/env/movie/lib/python3.5/site-packages/django/db/backends/base/schema.py:101] CREATE TABLE `auth_user` (`id` integer AUTO_INCREMENT NOT NULL PRIMARY KEY, `password` varchar(128) NOT NULL, `last_login` datetime(6) NOT NULL, `is_superuser` bool NOT NULL, `username` varchar(30) NOT NULL UNIQUE, `first_name` varchar(30) NOT NULL, `last_name` varchar(30) NOT NULL, `email` varchar(75) NOT NULL, `is_staff` bool NOT NULL, `is_active` bool NOT NULL, `date_joined` datetime(6) NOT NULL); (params None)
[22/Feb/2020 07:16:12] DEBUG [/home/thanhtran/workspace/python/env/movie/lib/python3.5/site-packages/django/db/backends/base/schema.py:101] CREATE TABLE `auth_user_groups` (`id` integer AUTO_INCREMENT NOT NULL PRIMARY KEY, `user_id` integer NOT NULL, `group_id` integer NOT NULL); (params None)
[22/Feb/2020 07:16:12] DEBUG [/home/thanhtran/workspace/python/env/movie/lib/python3.5/site-packages/django/db/backends/base/schema.py:101] CREATE TABLE `auth_user_user_permissions` (`id` integer AUTO_INCREMENT NOT NULL PRIMARY KEY, `user_id` integer NOT NULL, `permission_id` integer NOT NULL); (params None)
[22/Feb/2020 07:16:12] DEBUG [/home/thanhtran/workspace/python/env/movie/lib/python3.5/site-packages/django/db/backends/base/schema.py:101] ALTER TABLE `auth_permission` ADD CONSTRAINT `auth_permissi_content_type_id_2f476e4b_fk_django_content_type_id` FOREIGN KEY (`content_type_id`) REFERENCES `django_content_type` (`id`); (params [])
[22/Feb/2020 07:16:12] DEBUG [/home/thanhtran/workspace/python/env/movie/lib/python3.5/site-packages/django/db/backends/base/schema.py:101] ALTER TABLE `auth_permission` ADD CONSTRAINT `auth_permission_content_type_id_01ab375a_uniq` UNIQUE (`content_type_id`, `codename`); (params [])
[22/Feb/2020 07:16:12] DEBUG [/home/thanhtran/workspace/python/env/movie/lib/python3.5/site-packages/django/db/backends/base/schema.py:101] ALTER TABLE `auth_group_permissions` ADD CONSTRAINT `auth_group_permissions_group_id_b120cbf9_fk_auth_group_id` FOREIGN KEY (`group_id`) REFERENCES `auth_group` (`id`); (params [])
[22/Feb/2020 07:16:12] DEBUG [/home/thanhtran/workspace/python/env/movie/lib/python3.5/site-packages/django/db/backends/base/schema.py:101] ALTER TABLE `auth_group_permissions` ADD CONSTRAINT `auth_group_permissi_permission_id_84c5c92e_fk_auth_permission_id` FOREIGN KEY (`permission_id`) REFERENCES `auth_permission` (`id`); (params [])
[22/Feb/2020 07:16:13] DEBUG [/home/thanhtran/workspace/python/env/movie/lib/python3.5/site-packages/django/db/backends/base/schema.py:101] ALTER TABLE `auth_group_permissions` ADD CONSTRAINT `auth_group_permissions_group_id_0cd325b0_uniq` UNIQUE (`group_id`, `permission_id`); (params [])
[22/Feb/2020 07:16:13] DEBUG [/home/thanhtran/workspace/python/env/movie/lib/python3.5/site-packages/django/db/backends/base/schema.py:101] ALTER TABLE `auth_user_groups` ADD CONSTRAINT `auth_user_groups_user_id_6a12ed8b_fk_auth_user_id` FOREIGN KEY (`user_id`) REFERENCES `auth_user` (`id`); (params [])
[22/Feb/2020 07:16:13] DEBUG [/home/thanhtran/workspace/python/env/movie/lib/python3.5/site-packages/django/db/backends/base/schema.py:101] ALTER TABLE `auth_user_groups` ADD CONSTRAINT `auth_user_groups_group_id_97559544_fk_auth_group_id` FOREIGN KEY (`group_id`) REFERENCES `auth_group` (`id`); (params [])
[22/Feb/2020 07:16:13] DEBUG [/home/thanhtran/workspace/python/env/movie/lib/python3.5/site-packages/django/db/backends/base/schema.py:101] ALTER TABLE `auth_user_groups` ADD CONSTRAINT `auth_user_groups_user_id_94350c0c_uniq` UNIQUE (`user_id`, `group_id`); (params [])
[22/Feb/2020 07:16:13] DEBUG [/home/thanhtran/workspace/python/env/movie/lib/python3.5/site-packages/django/db/backends/base/schema.py:101] ALTER TABLE `auth_user_user_permissions` ADD CONSTRAINT `auth_user_user_permissions_user_id_a95ead1b_fk_auth_user_id` FOREIGN KEY (`user_id`) REFERENCES `auth_user` (`id`); (params [])
[22/Feb/2020 07:16:13] DEBUG [/home/thanhtran/workspace/python/env/movie/lib/python3.5/site-packages/django/db/backends/base/schema.py:101] ALTER TABLE `auth_user_user_permissions` ADD CONSTRAINT `auth_user_user_perm_permission_id_1fbb5f2c_fk_auth_permission_id` FOREIGN KEY (`permission_id`) REFERENCES `auth_permission` (`id`); (params [])
[22/Feb/2020 07:16:13] DEBUG [/home/thanhtran/workspace/python/env/movie/lib/python3.5/site-packages/django/db/backends/base/schema.py:101] ALTER TABLE `auth_user_user_permissions` ADD CONSTRAINT `auth_user_user_permissions_user_id_14a6b632_uniq` UNIQUE (`user_id`, `permission_id`); (params [])
[22/Feb/2020 07:16:13] DEBUG [/home/thanhtran/workspace/python/env/movie/lib/python3.5/site-packages/django/db/backends/base/schema.py:101] ALTER TABLE `auth_permission` MODIFY `name` varchar(255) NOT NULL; (params [])
[22/Feb/2020 07:16:13] DEBUG [/home/thanhtran/workspace/python/env/movie/lib/python3.5/site-packages/django/db/backends/base/schema.py:101] ALTER TABLE `auth_user` MODIFY `email` varchar(254) NOT NULL; (params [])
[22/Feb/2020 07:16:13] DEBUG [/home/thanhtran/workspace/python/env/movie/lib/python3.5/site-packages/django/db/backends/base/schema.py:101] ALTER TABLE `auth_user` MODIFY `last_login` datetime(6) NULL; (params [])
[22/Feb/2020 07:16:13] DEBUG [/home/thanhtran/workspace/python/env/movie/lib/python3.5/site-packages/django/db/backends/base/schema.py:101] CREATE TABLE `ai_customers` (`created_at` datetime(6) NOT NULL, `updated_at` datetime(6) NOT NULL, `id` integer AUTO_INCREMENT NOT NULL PRIMARY KEY, `name` varchar(255) NOT NULL); (params None)
[22/Feb/2020 07:16:13] DEBUG [/home/thanhtran/workspace/python/env/movie/lib/python3.5/site-packages/django/db/backends/base/schema.py:101] CREATE TABLE `ai_movies` (`created_at` datetime(6) NOT NULL, `updated_at` datetime(6) NOT NULL, `id` integer AUTO_INCREMENT NOT NULL PRIMARY KEY, `name` varchar(255) NOT NULL, `start_at` datetime(6) NULL, `minutes` tinyint NOT NULL); (params None)
[22/Feb/2020 07:16:13] DEBUG [/home/thanhtran/workspace/python/env/movie/lib/python3.5/site-packages/django/db/backends/base/schema.py:101] CREATE TABLE `ai_rooms` (`created_at` datetime(6) NOT NULL, `updated_at` datetime(6) NOT NULL, `id` integer AUTO_INCREMENT NOT NULL PRIMARY KEY, `name` varchar(255) NOT NULL, `seats` integer UNSIGNED NOT NULL); (params None)
[22/Feb/2020 07:16:13] DEBUG [/home/thanhtran/workspace/python/env/movie/lib/python3.5/site-packages/django/db/backends/base/schema.py:101] CREATE TABLE `ai_room_booking` (`created_at` datetime(6) NOT NULL, `updated_at` datetime(6) NOT NULL, `id` integer AUTO_INCREMENT NOT NULL PRIMARY KEY, `room_id` integer UNSIGNED NOT NULL, `movie_id` integer UNSIGNED NOT NULL, `booked_at` datetime(6) NULL, `booked_end_at` datetime(6) NULL); (params None)
[22/Feb/2020 07:16:13] DEBUG [/home/thanhtran/workspace/python/env/movie/lib/python3.5/site-packages/django/db/backends/base/schema.py:101] CREATE TABLE `ai_tickets` (`created_at` datetime(6) NOT NULL, `updated_at` datetime(6) NOT NULL, `id` integer AUTO_INCREMENT NOT NULL PRIMARY KEY, `room_id` integer UNSIGNED NOT NULL, `movie_id` integer UNSIGNED NOT NULL, `seat_number` integer UNSIGNED NOT NULL, `customer_id` integer UNSIGNED NOT NULL, `room_booking_id` integer UNSIGNED NOT NULL); (params None)
[22/Feb/2020 07:16:13] DEBUG [/home/thanhtran/workspace/python/env/movie/lib/python3.5/site-packages/django/db/backends/base/schema.py:101] CREATE INDEX `ai_room_booking_8273f993` ON `ai_room_booking` (`room_id`); (params [])
[22/Feb/2020 07:16:13] DEBUG [/home/thanhtran/workspace/python/env/movie/lib/python3.5/site-packages/django/db/backends/base/schema.py:101] CREATE INDEX `ai_room_booking_d1b173c8` ON `ai_room_booking` (`movie_id`); (params [])
[22/Feb/2020 07:16:13] DEBUG [/home/thanhtran/workspace/python/env/movie/lib/python3.5/site-packages/django/db/backends/base/schema.py:101] CREATE INDEX `ai_tickets_8273f993` ON `ai_tickets` (`room_id`); (params [])
[22/Feb/2020 07:16:14] DEBUG [/home/thanhtran/workspace/python/env/movie/lib/python3.5/site-packages/django/db/backends/base/schema.py:101] CREATE INDEX `ai_tickets_d1b173c8` ON `ai_tickets` (`movie_id`); (params [])
[22/Feb/2020 08:17:14] WARNING [/home/thanhtran/workspace/python/env/movie/lib/python3.5/site-packages/django/core/handlers/base.py:182] Not Found: /company
[22/Feb/2020 08:23:37] DEBUG [/home/thanhtran/workspace/python/env/movie/lib/python3.5/site-packages/django/db/backends/base/schema.py:101] ALTER TABLE `ai_movies` MODIFY `start_at` varchar(20) NULL; (params [])
[22/Feb/2020 08:23:37] DEBUG [/home/thanhtran/workspace/python/env/movie/lib/python3.5/site-packages/django/db/backends/base/schema.py:101] ALTER TABLE `ai_movies` ALTER COLUMN `start_at` SET DEFAULT %s; (params [''])
[22/Feb/2020 08:23:37] DEBUG [/home/thanhtran/workspace/python/env/movie/lib/python3.5/site-packages/django/db/backends/base/schema.py:101] UPDATE `ai_movies` SET `start_at` = %s WHERE `start_at` IS NULL; (params [''])
[22/Feb/2020 08:23:37] DEBUG [/home/thanhtran/workspace/python/env/movie/lib/python3.5/site-packages/django/db/backends/base/schema.py:101] ALTER TABLE `ai_movies` MODIFY `start_at` varchar(20) NOT NULL; (params [])
[22/Feb/2020 08:23:37] DEBUG [/home/thanhtran/workspace/python/env/movie/lib/python3.5/site-packages/django/db/backends/base/schema.py:101] ALTER TABLE `ai_movies` ALTER COLUMN `start_at` DROP DEFAULT; (params [])
[22/Feb/2020 08:43:21] DEBUG [/home/thanhtran/workspace/python/env/movie/lib/python3.5/site-packages/django/db/backends/base/schema.py:101] ALTER TABLE `ai_tickets` DROP COLUMN `movie_id` CASCADE; (params [])
[22/Feb/2020 08:43:21] DEBUG [/home/thanhtran/workspace/python/env/movie/lib/python3.5/site-packages/django/db/backends/base/schema.py:101] ALTER TABLE `ai_tickets` DROP COLUMN `room_id` CASCADE; (params [])
[22/Feb/2020 08:53:55] ERROR [/home/thanhtran/workspace/python/env/movie/lib/python3.5/site-packages/django/core/handlers/base.py:284] Internal Server Error: /ticket
Traceback (most recent call last):
  File "/home/thanhtran/workspace/python/env/movie/lib/python3.5/site-packages/rest_framework/fields.py", line 405, in get_attribute
    return get_attribute(instance, self.source_attrs)
  File "/home/thanhtran/workspace/python/env/movie/lib/python3.5/site-packages/rest_framework/fields.py", line 80, in get_attribute
    instance = getattr(instance, attr)
AttributeError: 'Ticket' object has no attribute 'customer_name'

During handling of the above exception, another exception occurred:

Traceback (most recent call last):
  File "/home/thanhtran/workspace/python/env/movie/lib/python3.5/site-packages/django/core/handlers/base.py", line 149, in get_response
    response = self.process_exception_by_middleware(e, request)
  File "/home/thanhtran/workspace/python/env/movie/lib/python3.5/site-packages/django/core/handlers/base.py", line 147, in get_response
    response = wrapped_callback(request, *callback_args, **callback_kwargs)
  File "/home/thanhtran/workspace/python/env/movie/lib/python3.5/site-packages/django/views/decorators/csrf.py", line 58, in wrapped_view
    return view_func(*args, **kwargs)
  File "/home/thanhtran/workspace/python/env/movie/lib/python3.5/site-packages/rest_framework/viewsets.py", line 87, in view
    return self.dispatch(request, *args, **kwargs)
  File "/home/thanhtran/workspace/python/env/movie/lib/python3.5/site-packages/rest_framework/views.py", line 466, in dispatch
    response = self.handle_exception(exc)
  File "/home/thanhtran/workspace/python/env/movie/lib/python3.5/site-packages/rest_framework/views.py", line 463, in dispatch
    response = handler(request, *args, **kwargs)
  File "/home/thanhtran/workspace/python/movie/core/views/ticket.py", line 20, in list
    'tickets': self.get_serializer(tickets, many=True).data
  File "/home/thanhtran/workspace/python/env/movie/lib/python3.5/site-packages/rest_framework/serializers.py", line 674, in data
    ret = super(ListSerializer, self).data
  File "/home/thanhtran/workspace/python/env/movie/lib/python3.5/site-packages/rest_framework/serializers.py", line 239, in data
    self._data = self.to_representation(self.instance)
  File "/home/thanhtran/workspace/python/env/movie/lib/python3.5/site-packages/rest_framework/serializers.py", line 614, in to_representation
    self.child.to_representation(item) for item in iterable
  File "/home/thanhtran/workspace/python/env/movie/lib/python3.5/site-packages/rest_framework/serializers.py", line 614, in <listcomp>
    self.child.to_representation(item) for item in iterable
  File "/home/thanhtran/workspace/python/env/movie/lib/python3.5/site-packages/rest_framework/serializers.py", line 463, in to_representation
    attribute = field.get_attribute(instance)
  File "/home/thanhtran/workspace/python/env/movie/lib/python3.5/site-packages/rest_framework/fields.py", line 422, in get_attribute
    raise type(exc)(msg)
AttributeError: Got AttributeError when attempting to get a value for field `customer_name` on serializer `TicketSerializer`.
The serializer field might be named incorrectly and not match any attribute or key on the `Ticket` instance.
Original exception text was: 'Ticket' object has no attribute 'customer_name'.
[22/Feb/2020 08:53:57] ERROR [/home/thanhtran/workspace/python/env/movie/lib/python3.5/site-packages/django/core/handlers/base.py:284] Internal Server Error: /ticket
Traceback (most recent call last):
  File "/home/thanhtran/workspace/python/env/movie/lib/python3.5/site-packages/rest_framework/fields.py", line 405, in get_attribute
    return get_attribute(instance, self.source_attrs)
  File "/home/thanhtran/workspace/python/env/movie/lib/python3.5/site-packages/rest_framework/fields.py", line 80, in get_attribute
    instance = getattr(instance, attr)
AttributeError: 'Ticket' object has no attribute 'customer_name'

During handling of the above exception, another exception occurred:

Traceback (most recent call last):
  File "/home/thanhtran/workspace/python/env/movie/lib/python3.5/site-packages/django/core/handlers/base.py", line 149, in get_response
    response = self.process_exception_by_middleware(e, request)
  File "/home/thanhtran/workspace/python/env/movie/lib/python3.5/site-packages/django/core/handlers/base.py", line 147, in get_response
    response = wrapped_callback(request, *callback_args, **callback_kwargs)
  File "/home/thanhtran/workspace/python/env/movie/lib/python3.5/site-packages/django/views/decorators/csrf.py", line 58, in wrapped_view
    return view_func(*args, **kwargs)
  File "/home/thanhtran/workspace/python/env/movie/lib/python3.5/site-packages/rest_framework/viewsets.py", line 87, in view
    return self.dispatch(request, *args, **kwargs)
  File "/home/thanhtran/workspace/python/env/movie/lib/python3.5/site-packages/rest_framework/views.py", line 466, in dispatch
    response = self.handle_exception(exc)
  File "/home/thanhtran/workspace/python/env/movie/lib/python3.5/site-packages/rest_framework/views.py", line 463, in dispatch
    response = handler(request, *args, **kwargs)
  File "/home/thanhtran/workspace/python/movie/core/views/ticket.py", line 20, in list
    'tickets': self.get_serializer(tickets, many=True).data
  File "/home/thanhtran/workspace/python/env/movie/lib/python3.5/site-packages/rest_framework/serializers.py", line 674, in data
    ret = super(ListSerializer, self).data
  File "/home/thanhtran/workspace/python/env/movie/lib/python3.5/site-packages/rest_framework/serializers.py", line 239, in data
    self._data = self.to_representation(self.instance)
  File "/home/thanhtran/workspace/python/env/movie/lib/python3.5/site-packages/rest_framework/serializers.py", line 614, in to_representation
    self.child.to_representation(item) for item in iterable
  File "/home/thanhtran/workspace/python/env/movie/lib/python3.5/site-packages/rest_framework/serializers.py", line 614, in <listcomp>
    self.child.to_representation(item) for item in iterable
  File "/home/thanhtran/workspace/python/env/movie/lib/python3.5/site-packages/rest_framework/serializers.py", line 463, in to_representation
    attribute = field.get_attribute(instance)
  File "/home/thanhtran/workspace/python/env/movie/lib/python3.5/site-packages/rest_framework/fields.py", line 422, in get_attribute
    raise type(exc)(msg)
AttributeError: Got AttributeError when attempting to get a value for field `customer_name` on serializer `TicketSerializer`.
The serializer field might be named incorrectly and not match any attribute or key on the `Ticket` instance.
Original exception text was: 'Ticket' object has no attribute 'customer_name'.
[22/Feb/2020 08:54:19] ERROR [/home/thanhtran/workspace/python/env/movie/lib/python3.5/site-packages/django/core/handlers/base.py:284] Internal Server Error: /ticket
Traceback (most recent call last):
  File "/home/thanhtran/workspace/python/env/movie/lib/python3.5/site-packages/rest_framework/fields.py", line 405, in get_attribute
    return get_attribute(instance, self.source_attrs)
  File "/home/thanhtran/workspace/python/env/movie/lib/python3.5/site-packages/rest_framework/fields.py", line 80, in get_attribute
    instance = getattr(instance, attr)
AttributeError: 'Ticket' object has no attribute 'customer_name'

During handling of the above exception, another exception occurred:

Traceback (most recent call last):
  File "/home/thanhtran/workspace/python/env/movie/lib/python3.5/site-packages/django/core/handlers/base.py", line 149, in get_response
    response = self.process_exception_by_middleware(e, request)
  File "/home/thanhtran/workspace/python/env/movie/lib/python3.5/site-packages/django/core/handlers/base.py", line 147, in get_response
    response = wrapped_callback(request, *callback_args, **callback_kwargs)
  File "/home/thanhtran/workspace/python/env/movie/lib/python3.5/site-packages/django/views/decorators/csrf.py", line 58, in wrapped_view
    return view_func(*args, **kwargs)
  File "/home/thanhtran/workspace/python/env/movie/lib/python3.5/site-packages/rest_framework/viewsets.py", line 87, in view
    return self.dispatch(request, *args, **kwargs)
  File "/home/thanhtran/workspace/python/env/movie/lib/python3.5/site-packages/rest_framework/views.py", line 466, in dispatch
    response = self.handle_exception(exc)
  File "/home/thanhtran/workspace/python/env/movie/lib/python3.5/site-packages/rest_framework/views.py", line 463, in dispatch
    response = handler(request, *args, **kwargs)
  File "/home/thanhtran/workspace/python/movie/core/views/ticket.py", line 46, in create
    raise ex
  File "/home/thanhtran/workspace/python/movie/core/views/ticket.py", line 43, in create
    return Response(serializer.data, status=status.HTTP_200_OK)
  File "/home/thanhtran/workspace/python/env/movie/lib/python3.5/site-packages/rest_framework/serializers.py", line 503, in data
    ret = super(Serializer, self).data
  File "/home/thanhtran/workspace/python/env/movie/lib/python3.5/site-packages/rest_framework/serializers.py", line 239, in data
    self._data = self.to_representation(self.instance)
  File "/home/thanhtran/workspace/python/env/movie/lib/python3.5/site-packages/rest_framework/serializers.py", line 463, in to_representation
    attribute = field.get_attribute(instance)
  File "/home/thanhtran/workspace/python/env/movie/lib/python3.5/site-packages/rest_framework/fields.py", line 422, in get_attribute
    raise type(exc)(msg)
AttributeError: Got AttributeError when attempting to get a value for field `customer_name` on serializer `TicketSerializer`.
The serializer field might be named incorrectly and not match any attribute or key on the `Ticket` instance.
Original exception text was: 'Ticket' object has no attribute 'customer_name'.
[22/Feb/2020 08:54:53] ERROR [/home/thanhtran/workspace/python/env/movie/lib/python3.5/site-packages/django/core/handlers/base.py:284] Internal Server Error: /ticket
Traceback (most recent call last):
  File "/home/thanhtran/workspace/python/env/movie/lib/python3.5/site-packages/rest_framework/fields.py", line 405, in get_attribute
    return get_attribute(instance, self.source_attrs)
  File "/home/thanhtran/workspace/python/env/movie/lib/python3.5/site-packages/rest_framework/fields.py", line 80, in get_attribute
    instance = getattr(instance, attr)
AttributeError: 'Ticket' object has no attribute 'customer_name'

During handling of the above exception, another exception occurred:

Traceback (most recent call last):
  File "/home/thanhtran/workspace/python/env/movie/lib/python3.5/site-packages/django/core/handlers/base.py", line 149, in get_response
    response = self.process_exception_by_middleware(e, request)
  File "/home/thanhtran/workspace/python/env/movie/lib/python3.5/site-packages/django/core/handlers/base.py", line 147, in get_response
    response = wrapped_callback(request, *callback_args, **callback_kwargs)
  File "/home/thanhtran/workspace/python/env/movie/lib/python3.5/site-packages/django/views/decorators/csrf.py", line 58, in wrapped_view
    return view_func(*args, **kwargs)
  File "/home/thanhtran/workspace/python/env/movie/lib/python3.5/site-packages/rest_framework/viewsets.py", line 87, in view
    return self.dispatch(request, *args, **kwargs)
  File "/home/thanhtran/workspace/python/env/movie/lib/python3.5/site-packages/rest_framework/views.py", line 466, in dispatch
    response = self.handle_exception(exc)
  File "/home/thanhtran/workspace/python/env/movie/lib/python3.5/site-packages/rest_framework/views.py", line 463, in dispatch
    response = handler(request, *args, **kwargs)
  File "/home/thanhtran/workspace/python/movie/core/views/ticket.py", line 20, in list
    'tickets': self.get_serializer(tickets, many=True).data
  File "/home/thanhtran/workspace/python/env/movie/lib/python3.5/site-packages/rest_framework/serializers.py", line 674, in data
    ret = super(ListSerializer, self).data
  File "/home/thanhtran/workspace/python/env/movie/lib/python3.5/site-packages/rest_framework/serializers.py", line 239, in data
    self._data = self.to_representation(self.instance)
  File "/home/thanhtran/workspace/python/env/movie/lib/python3.5/site-packages/rest_framework/serializers.py", line 614, in to_representation
    self.child.to_representation(item) for item in iterable
  File "/home/thanhtran/workspace/python/env/movie/lib/python3.5/site-packages/rest_framework/serializers.py", line 614, in <listcomp>
    self.child.to_representation(item) for item in iterable
  File "/home/thanhtran/workspace/python/env/movie/lib/python3.5/site-packages/rest_framework/serializers.py", line 463, in to_representation
    attribute = field.get_attribute(instance)
  File "/home/thanhtran/workspace/python/env/movie/lib/python3.5/site-packages/rest_framework/fields.py", line 422, in get_attribute
    raise type(exc)(msg)
AttributeError: Got AttributeError when attempting to get a value for field `customer_name` on serializer `TicketSerializer`.
The serializer field might be named incorrectly and not match any attribute or key on the `Ticket` instance.
Original exception text was: 'Ticket' object has no attribute 'customer_name'.
[22/Feb/2020 08:54:59] ERROR [/home/thanhtran/workspace/python/env/movie/lib/python3.5/site-packages/django/core/handlers/base.py:284] Internal Server Error: /ticket
Traceback (most recent call last):
  File "/home/thanhtran/workspace/python/env/movie/lib/python3.5/site-packages/rest_framework/fields.py", line 405, in get_attribute
    return get_attribute(instance, self.source_attrs)
  File "/home/thanhtran/workspace/python/env/movie/lib/python3.5/site-packages/rest_framework/fields.py", line 80, in get_attribute
    instance = getattr(instance, attr)
AttributeError: 'Ticket' object has no attribute 'customer_name'

During handling of the above exception, another exception occurred:

Traceback (most recent call last):
  File "/home/thanhtran/workspace/python/env/movie/lib/python3.5/site-packages/django/core/handlers/base.py", line 149, in get_response
    response = self.process_exception_by_middleware(e, request)
  File "/home/thanhtran/workspace/python/env/movie/lib/python3.5/site-packages/django/core/handlers/base.py", line 147, in get_response
    response = wrapped_callback(request, *callback_args, **callback_kwargs)
  File "/home/thanhtran/workspace/python/env/movie/lib/python3.5/site-packages/django/views/decorators/csrf.py", line 58, in wrapped_view
    return view_func(*args, **kwargs)
  File "/home/thanhtran/workspace/python/env/movie/lib/python3.5/site-packages/rest_framework/viewsets.py", line 87, in view
    return self.dispatch(request, *args, **kwargs)
  File "/home/thanhtran/workspace/python/env/movie/lib/python3.5/site-packages/rest_framework/views.py", line 466, in dispatch
    response = self.handle_exception(exc)
  File "/home/thanhtran/workspace/python/env/movie/lib/python3.5/site-packages/rest_framework/views.py", line 463, in dispatch
    response = handler(request, *args, **kwargs)
  File "/home/thanhtran/workspace/python/movie/core/views/ticket.py", line 20, in list
    'tickets': self.get_serializer(tickets, many=True).data
  File "/home/thanhtran/workspace/python/env/movie/lib/python3.5/site-packages/rest_framework/serializers.py", line 674, in data
    ret = super(ListSerializer, self).data
  File "/home/thanhtran/workspace/python/env/movie/lib/python3.5/site-packages/rest_framework/serializers.py", line 239, in data
    self._data = self.to_representation(self.instance)
  File "/home/thanhtran/workspace/python/env/movie/lib/python3.5/site-packages/rest_framework/serializers.py", line 614, in to_representation
    self.child.to_representation(item) for item in iterable
  File "/home/thanhtran/workspace/python/env/movie/lib/python3.5/site-packages/rest_framework/serializers.py", line 614, in <listcomp>
    self.child.to_representation(item) for item in iterable
  File "/home/thanhtran/workspace/python/env/movie/lib/python3.5/site-packages/rest_framework/serializers.py", line 463, in to_representation
    attribute = field.get_attribute(instance)
  File "/home/thanhtran/workspace/python/env/movie/lib/python3.5/site-packages/rest_framework/fields.py", line 422, in get_attribute
    raise type(exc)(msg)
AttributeError: Got AttributeError when attempting to get a value for field `customer_name` on serializer `TicketSerializer`.
The serializer field might be named incorrectly and not match any attribute or key on the `Ticket` instance.
Original exception text was: 'Ticket' object has no attribute 'customer_name'.
[22/Feb/2020 08:55:34] ERROR [/home/thanhtran/workspace/python/env/movie/lib/python3.5/site-packages/django/core/handlers/base.py:284] Internal Server Error: /ticket
Traceback (most recent call last):
  File "/home/thanhtran/workspace/python/env/movie/lib/python3.5/site-packages/rest_framework/fields.py", line 405, in get_attribute
    return get_attribute(instance, self.source_attrs)
  File "/home/thanhtran/workspace/python/env/movie/lib/python3.5/site-packages/rest_framework/fields.py", line 80, in get_attribute
    instance = getattr(instance, attr)
AttributeError: 'Ticket' object has no attribute 'customer_name'

During handling of the above exception, another exception occurred:

Traceback (most recent call last):
  File "/home/thanhtran/workspace/python/env/movie/lib/python3.5/site-packages/django/core/handlers/base.py", line 149, in get_response
    response = self.process_exception_by_middleware(e, request)
  File "/home/thanhtran/workspace/python/env/movie/lib/python3.5/site-packages/django/core/handlers/base.py", line 147, in get_response
    response = wrapped_callback(request, *callback_args, **callback_kwargs)
  File "/home/thanhtran/workspace/python/env/movie/lib/python3.5/site-packages/django/views/decorators/csrf.py", line 58, in wrapped_view
    return view_func(*args, **kwargs)
  File "/home/thanhtran/workspace/python/env/movie/lib/python3.5/site-packages/rest_framework/viewsets.py", line 87, in view
    return self.dispatch(request, *args, **kwargs)
  File "/home/thanhtran/workspace/python/env/movie/lib/python3.5/site-packages/rest_framework/views.py", line 466, in dispatch
    response = self.handle_exception(exc)
  File "/home/thanhtran/workspace/python/env/movie/lib/python3.5/site-packages/rest_framework/views.py", line 463, in dispatch
    response = handler(request, *args, **kwargs)
  File "/home/thanhtran/workspace/python/movie/core/views/ticket.py", line 20, in list
    'tickets': self.get_serializer(tickets, many=True).data
  File "/home/thanhtran/workspace/python/env/movie/lib/python3.5/site-packages/rest_framework/serializers.py", line 674, in data
    ret = super(ListSerializer, self).data
  File "/home/thanhtran/workspace/python/env/movie/lib/python3.5/site-packages/rest_framework/serializers.py", line 239, in data
    self._data = self.to_representation(self.instance)
  File "/home/thanhtran/workspace/python/env/movie/lib/python3.5/site-packages/rest_framework/serializers.py", line 614, in to_representation
    self.child.to_representation(item) for item in iterable
  File "/home/thanhtran/workspace/python/env/movie/lib/python3.5/site-packages/rest_framework/serializers.py", line 614, in <listcomp>
    self.child.to_representation(item) for item in iterable
  File "/home/thanhtran/workspace/python/env/movie/lib/python3.5/site-packages/rest_framework/serializers.py", line 463, in to_representation
    attribute = field.get_attribute(instance)
  File "/home/thanhtran/workspace/python/env/movie/lib/python3.5/site-packages/rest_framework/fields.py", line 422, in get_attribute
    raise type(exc)(msg)
AttributeError: Got AttributeError when attempting to get a value for field `customer_name` on serializer `TicketSerializer`.
The serializer field might be named incorrectly and not match any attribute or key on the `Ticket` instance.
Original exception text was: 'Ticket' object has no attribute 'customer_name'.
[22/Feb/2020 08:59:23] ERROR [/home/thanhtran/workspace/python/env/movie/lib/python3.5/site-packages/django/core/handlers/base.py:284] Internal Server Error: /ticket
Traceback (most recent call last):
  File "/home/thanhtran/workspace/python/env/movie/lib/python3.5/site-packages/django/db/backends/utils.py", line 64, in execute
    return self.cursor.execute(sql, params)
  File "/home/thanhtran/workspace/python/env/movie/lib/python3.5/site-packages/django/db/backends/mysql/base.py", line 112, in execute
    return self.cursor.execute(query, args)
  File "/home/thanhtran/workspace/python/env/movie/lib/python3.5/site-packages/MySQLdb/cursors.py", line 250, in execute
    self.errorhandler(self, exc, value)
  File "/home/thanhtran/workspace/python/env/movie/lib/python3.5/site-packages/MySQLdb/connections.py", line 50, in defaulterrorhandler
    raise errorvalue
  File "/home/thanhtran/workspace/python/env/movie/lib/python3.5/site-packages/MySQLdb/cursors.py", line 247, in execute
    res = self._query(query)
  File "/home/thanhtran/workspace/python/env/movie/lib/python3.5/site-packages/MySQLdb/cursors.py", line 411, in _query
    rowcount = self._do_query(q)
  File "/home/thanhtran/workspace/python/env/movie/lib/python3.5/site-packages/MySQLdb/cursors.py", line 374, in _do_query
    db.query(q)
  File "/home/thanhtran/workspace/python/env/movie/lib/python3.5/site-packages/MySQLdb/connections.py", line 292, in query
    _mysql.connection.query(self, query)
_mysql_exceptions.OperationalError: (1054, "Unknown column 'ai_tickets.customer_name' in 'field list'")

The above exception was the direct cause of the following exception:

Traceback (most recent call last):
  File "/home/thanhtran/workspace/python/env/movie/lib/python3.5/site-packages/django/core/handlers/base.py", line 149, in get_response
    response = self.process_exception_by_middleware(e, request)
  File "/home/thanhtran/workspace/python/env/movie/lib/python3.5/site-packages/django/core/handlers/base.py", line 147, in get_response
    response = wrapped_callback(request, *callback_args, **callback_kwargs)
  File "/home/thanhtran/workspace/python/env/movie/lib/python3.5/site-packages/django/views/decorators/csrf.py", line 58, in wrapped_view
    return view_func(*args, **kwargs)
  File "/home/thanhtran/workspace/python/env/movie/lib/python3.5/site-packages/rest_framework/viewsets.py", line 87, in view
    return self.dispatch(request, *args, **kwargs)
  File "/home/thanhtran/workspace/python/env/movie/lib/python3.5/site-packages/rest_framework/views.py", line 466, in dispatch
    response = self.handle_exception(exc)
  File "/home/thanhtran/workspace/python/env/movie/lib/python3.5/site-packages/rest_framework/views.py", line 463, in dispatch
    response = handler(request, *args, **kwargs)
  File "/home/thanhtran/workspace/python/movie/core/views/ticket.py", line 20, in list
    'tickets': self.get_serializer(tickets, many=True).data
  File "/home/thanhtran/workspace/python/env/movie/lib/python3.5/site-packages/rest_framework/serializers.py", line 674, in data
    ret = super(ListSerializer, self).data
  File "/home/thanhtran/workspace/python/env/movie/lib/python3.5/site-packages/rest_framework/serializers.py", line 239, in data
    self._data = self.to_representation(self.instance)
  File "/home/thanhtran/workspace/python/env/movie/lib/python3.5/site-packages/rest_framework/serializers.py", line 614, in to_representation
    self.child.to_representation(item) for item in iterable
  File "/home/thanhtran/workspace/python/env/movie/lib/python3.5/site-packages/django/db/models/query.py", line 258, in __iter__
    self._fetch_all()
  File "/home/thanhtran/workspace/python/env/movie/lib/python3.5/site-packages/django/db/models/query.py", line 1074, in _fetch_all
    self._result_cache = list(self.iterator())
  File "/home/thanhtran/workspace/python/env/movie/lib/python3.5/site-packages/django/db/models/query.py", line 52, in __iter__
    results = compiler.execute_sql()
  File "/home/thanhtran/workspace/python/env/movie/lib/python3.5/site-packages/django/db/models/sql/compiler.py", line 848, in execute_sql
    cursor.execute(sql, params)
  File "/home/thanhtran/workspace/python/env/movie/lib/python3.5/site-packages/django/db/backends/utils.py", line 64, in execute
    return self.cursor.execute(sql, params)
  File "/home/thanhtran/workspace/python/env/movie/lib/python3.5/site-packages/django/db/utils.py", line 95, in __exit__
    six.reraise(dj_exc_type, dj_exc_value, traceback)
  File "/home/thanhtran/workspace/python/env/movie/lib/python3.5/site-packages/django/utils/six.py", line 685, in reraise
    raise value.with_traceback(tb)
  File "/home/thanhtran/workspace/python/env/movie/lib/python3.5/site-packages/django/db/backends/utils.py", line 64, in execute
    return self.cursor.execute(sql, params)
  File "/home/thanhtran/workspace/python/env/movie/lib/python3.5/site-packages/django/db/backends/mysql/base.py", line 112, in execute
    return self.cursor.execute(query, args)
  File "/home/thanhtran/workspace/python/env/movie/lib/python3.5/site-packages/MySQLdb/cursors.py", line 250, in execute
    self.errorhandler(self, exc, value)
  File "/home/thanhtran/workspace/python/env/movie/lib/python3.5/site-packages/MySQLdb/connections.py", line 50, in defaulterrorhandler
    raise errorvalue
  File "/home/thanhtran/workspace/python/env/movie/lib/python3.5/site-packages/MySQLdb/cursors.py", line 247, in execute
    res = self._query(query)
  File "/home/thanhtran/workspace/python/env/movie/lib/python3.5/site-packages/MySQLdb/cursors.py", line 411, in _query
    rowcount = self._do_query(q)
  File "/home/thanhtran/workspace/python/env/movie/lib/python3.5/site-packages/MySQLdb/cursors.py", line 374, in _do_query
    db.query(q)
  File "/home/thanhtran/workspace/python/env/movie/lib/python3.5/site-packages/MySQLdb/connections.py", line 292, in query
    _mysql.connection.query(self, query)
django.db.utils.OperationalError: (1054, "Unknown column 'ai_tickets.customer_name' in 'field list'")
[22/Feb/2020 08:59:48] ERROR [/home/thanhtran/workspace/python/env/movie/lib/python3.5/site-packages/django/core/handlers/base.py:284] Internal Server Error: /ticket
Traceback (most recent call last):
  File "/home/thanhtran/workspace/python/env/movie/lib/python3.5/site-packages/django/db/backends/utils.py", line 64, in execute
    return self.cursor.execute(sql, params)
  File "/home/thanhtran/workspace/python/env/movie/lib/python3.5/site-packages/django/db/backends/mysql/base.py", line 112, in execute
    return self.cursor.execute(query, args)
  File "/home/thanhtran/workspace/python/env/movie/lib/python3.5/site-packages/MySQLdb/cursors.py", line 250, in execute
    self.errorhandler(self, exc, value)
  File "/home/thanhtran/workspace/python/env/movie/lib/python3.5/site-packages/MySQLdb/connections.py", line 50, in defaulterrorhandler
    raise errorvalue
  File "/home/thanhtran/workspace/python/env/movie/lib/python3.5/site-packages/MySQLdb/cursors.py", line 247, in execute
    res = self._query(query)
  File "/home/thanhtran/workspace/python/env/movie/lib/python3.5/site-packages/MySQLdb/cursors.py", line 411, in _query
    rowcount = self._do_query(q)
  File "/home/thanhtran/workspace/python/env/movie/lib/python3.5/site-packages/MySQLdb/cursors.py", line 374, in _do_query
    db.query(q)
  File "/home/thanhtran/workspace/python/env/movie/lib/python3.5/site-packages/MySQLdb/connections.py", line 292, in query
    _mysql.connection.query(self, query)
_mysql_exceptions.OperationalError: (1054, "Unknown column 'ai_tickets.customer_name' in 'field list'")

The above exception was the direct cause of the following exception:

Traceback (most recent call last):
  File "/home/thanhtran/workspace/python/env/movie/lib/python3.5/site-packages/django/core/handlers/base.py", line 149, in get_response
    response = self.process_exception_by_middleware(e, request)
  File "/home/thanhtran/workspace/python/env/movie/lib/python3.5/site-packages/django/core/handlers/base.py", line 147, in get_response
    response = wrapped_callback(request, *callback_args, **callback_kwargs)
  File "/home/thanhtran/workspace/python/env/movie/lib/python3.5/site-packages/django/views/decorators/csrf.py", line 58, in wrapped_view
    return view_func(*args, **kwargs)
  File "/home/thanhtran/workspace/python/env/movie/lib/python3.5/site-packages/rest_framework/viewsets.py", line 87, in view
    return self.dispatch(request, *args, **kwargs)
  File "/home/thanhtran/workspace/python/env/movie/lib/python3.5/site-packages/rest_framework/views.py", line 466, in dispatch
    response = self.handle_exception(exc)
  File "/home/thanhtran/workspace/python/env/movie/lib/python3.5/site-packages/rest_framework/views.py", line 463, in dispatch
    response = handler(request, *args, **kwargs)
  File "/home/thanhtran/workspace/python/movie/core/views/ticket.py", line 20, in list
    'tickets': self.get_serializer(tickets, many=True).data
  File "/home/thanhtran/workspace/python/env/movie/lib/python3.5/site-packages/rest_framework/serializers.py", line 674, in data
    ret = super(ListSerializer, self).data
  File "/home/thanhtran/workspace/python/env/movie/lib/python3.5/site-packages/rest_framework/serializers.py", line 239, in data
    self._data = self.to_representation(self.instance)
  File "/home/thanhtran/workspace/python/env/movie/lib/python3.5/site-packages/rest_framework/serializers.py", line 614, in to_representation
    self.child.to_representation(item) for item in iterable
  File "/home/thanhtran/workspace/python/env/movie/lib/python3.5/site-packages/django/db/models/query.py", line 258, in __iter__
    self._fetch_all()
  File "/home/thanhtran/workspace/python/env/movie/lib/python3.5/site-packages/django/db/models/query.py", line 1074, in _fetch_all
    self._result_cache = list(self.iterator())
  File "/home/thanhtran/workspace/python/env/movie/lib/python3.5/site-packages/django/db/models/query.py", line 52, in __iter__
    results = compiler.execute_sql()
  File "/home/thanhtran/workspace/python/env/movie/lib/python3.5/site-packages/django/db/models/sql/compiler.py", line 848, in execute_sql
    cursor.execute(sql, params)
  File "/home/thanhtran/workspace/python/env/movie/lib/python3.5/site-packages/django/db/backends/utils.py", line 64, in execute
    return self.cursor.execute(sql, params)
  File "/home/thanhtran/workspace/python/env/movie/lib/python3.5/site-packages/django/db/utils.py", line 95, in __exit__
    six.reraise(dj_exc_type, dj_exc_value, traceback)
  File "/home/thanhtran/workspace/python/env/movie/lib/python3.5/site-packages/django/utils/six.py", line 685, in reraise
    raise value.with_traceback(tb)
  File "/home/thanhtran/workspace/python/env/movie/lib/python3.5/site-packages/django/db/backends/utils.py", line 64, in execute
    return self.cursor.execute(sql, params)
  File "/home/thanhtran/workspace/python/env/movie/lib/python3.5/site-packages/django/db/backends/mysql/base.py", line 112, in execute
    return self.cursor.execute(query, args)
  File "/home/thanhtran/workspace/python/env/movie/lib/python3.5/site-packages/MySQLdb/cursors.py", line 250, in execute
    self.errorhandler(self, exc, value)
  File "/home/thanhtran/workspace/python/env/movie/lib/python3.5/site-packages/MySQLdb/connections.py", line 50, in defaulterrorhandler
    raise errorvalue
  File "/home/thanhtran/workspace/python/env/movie/lib/python3.5/site-packages/MySQLdb/cursors.py", line 247, in execute
    res = self._query(query)
  File "/home/thanhtran/workspace/python/env/movie/lib/python3.5/site-packages/MySQLdb/cursors.py", line 411, in _query
    rowcount = self._do_query(q)
  File "/home/thanhtran/workspace/python/env/movie/lib/python3.5/site-packages/MySQLdb/cursors.py", line 374, in _do_query
    db.query(q)
  File "/home/thanhtran/workspace/python/env/movie/lib/python3.5/site-packages/MySQLdb/connections.py", line 292, in query
    _mysql.connection.query(self, query)
django.db.utils.OperationalError: (1054, "Unknown column 'ai_tickets.customer_name' in 'field list'")
[22/Feb/2020 08:59:59] ERROR [/home/thanhtran/workspace/python/env/movie/lib/python3.5/site-packages/django/core/handlers/base.py:284] Internal Server Error: /ticket
Traceback (most recent call last):
  File "/home/thanhtran/workspace/python/env/movie/lib/python3.5/site-packages/django/db/backends/utils.py", line 64, in execute
    return self.cursor.execute(sql, params)
  File "/home/thanhtran/workspace/python/env/movie/lib/python3.5/site-packages/django/db/backends/mysql/base.py", line 112, in execute
    return self.cursor.execute(query, args)
  File "/home/thanhtran/workspace/python/env/movie/lib/python3.5/site-packages/MySQLdb/cursors.py", line 250, in execute
    self.errorhandler(self, exc, value)
  File "/home/thanhtran/workspace/python/env/movie/lib/python3.5/site-packages/MySQLdb/connections.py", line 50, in defaulterrorhandler
    raise errorvalue
  File "/home/thanhtran/workspace/python/env/movie/lib/python3.5/site-packages/MySQLdb/cursors.py", line 247, in execute
    res = self._query(query)
  File "/home/thanhtran/workspace/python/env/movie/lib/python3.5/site-packages/MySQLdb/cursors.py", line 411, in _query
    rowcount = self._do_query(q)
  File "/home/thanhtran/workspace/python/env/movie/lib/python3.5/site-packages/MySQLdb/cursors.py", line 374, in _do_query
    db.query(q)
  File "/home/thanhtran/workspace/python/env/movie/lib/python3.5/site-packages/MySQLdb/connections.py", line 292, in query
    _mysql.connection.query(self, query)
_mysql_exceptions.OperationalError: (1054, "Unknown column 'ai_tickets.customer_name' in 'field list'")

The above exception was the direct cause of the following exception:

Traceback (most recent call last):
  File "/home/thanhtran/workspace/python/env/movie/lib/python3.5/site-packages/django/core/handlers/base.py", line 149, in get_response
    response = self.process_exception_by_middleware(e, request)
  File "/home/thanhtran/workspace/python/env/movie/lib/python3.5/site-packages/django/core/handlers/base.py", line 147, in get_response
    response = wrapped_callback(request, *callback_args, **callback_kwargs)
  File "/home/thanhtran/workspace/python/env/movie/lib/python3.5/site-packages/django/views/decorators/csrf.py", line 58, in wrapped_view
    return view_func(*args, **kwargs)
  File "/home/thanhtran/workspace/python/env/movie/lib/python3.5/site-packages/rest_framework/viewsets.py", line 87, in view
    return self.dispatch(request, *args, **kwargs)
  File "/home/thanhtran/workspace/python/env/movie/lib/python3.5/site-packages/rest_framework/views.py", line 466, in dispatch
    response = self.handle_exception(exc)
  File "/home/thanhtran/workspace/python/env/movie/lib/python3.5/site-packages/rest_framework/views.py", line 463, in dispatch
    response = handler(request, *args, **kwargs)
  File "/home/thanhtran/workspace/python/movie/core/views/ticket.py", line 20, in list
    'tickets': self.get_serializer(tickets, many=True).data
  File "/home/thanhtran/workspace/python/env/movie/lib/python3.5/site-packages/rest_framework/serializers.py", line 674, in data
    ret = super(ListSerializer, self).data
  File "/home/thanhtran/workspace/python/env/movie/lib/python3.5/site-packages/rest_framework/serializers.py", line 239, in data
    self._data = self.to_representation(self.instance)
  File "/home/thanhtran/workspace/python/env/movie/lib/python3.5/site-packages/rest_framework/serializers.py", line 614, in to_representation
    self.child.to_representation(item) for item in iterable
  File "/home/thanhtran/workspace/python/env/movie/lib/python3.5/site-packages/django/db/models/query.py", line 258, in __iter__
    self._fetch_all()
  File "/home/thanhtran/workspace/python/env/movie/lib/python3.5/site-packages/django/db/models/query.py", line 1074, in _fetch_all
    self._result_cache = list(self.iterator())
  File "/home/thanhtran/workspace/python/env/movie/lib/python3.5/site-packages/django/db/models/query.py", line 52, in __iter__
    results = compiler.execute_sql()
  File "/home/thanhtran/workspace/python/env/movie/lib/python3.5/site-packages/django/db/models/sql/compiler.py", line 848, in execute_sql
    cursor.execute(sql, params)
  File "/home/thanhtran/workspace/python/env/movie/lib/python3.5/site-packages/django/db/backends/utils.py", line 64, in execute
    return self.cursor.execute(sql, params)
  File "/home/thanhtran/workspace/python/env/movie/lib/python3.5/site-packages/django/db/utils.py", line 95, in __exit__
    six.reraise(dj_exc_type, dj_exc_value, traceback)
  File "/home/thanhtran/workspace/python/env/movie/lib/python3.5/site-packages/django/utils/six.py", line 685, in reraise
    raise value.with_traceback(tb)
  File "/home/thanhtran/workspace/python/env/movie/lib/python3.5/site-packages/django/db/backends/utils.py", line 64, in execute
    return self.cursor.execute(sql, params)
  File "/home/thanhtran/workspace/python/env/movie/lib/python3.5/site-packages/django/db/backends/mysql/base.py", line 112, in execute
    return self.cursor.execute(query, args)
  File "/home/thanhtran/workspace/python/env/movie/lib/python3.5/site-packages/MySQLdb/cursors.py", line 250, in execute
    self.errorhandler(self, exc, value)
  File "/home/thanhtran/workspace/python/env/movie/lib/python3.5/site-packages/MySQLdb/connections.py", line 50, in defaulterrorhandler
    raise errorvalue
  File "/home/thanhtran/workspace/python/env/movie/lib/python3.5/site-packages/MySQLdb/cursors.py", line 247, in execute
    res = self._query(query)
  File "/home/thanhtran/workspace/python/env/movie/lib/python3.5/site-packages/MySQLdb/cursors.py", line 411, in _query
    rowcount = self._do_query(q)
  File "/home/thanhtran/workspace/python/env/movie/lib/python3.5/site-packages/MySQLdb/cursors.py", line 374, in _do_query
    db.query(q)
  File "/home/thanhtran/workspace/python/env/movie/lib/python3.5/site-packages/MySQLdb/connections.py", line 292, in query
    _mysql.connection.query(self, query)
django.db.utils.OperationalError: (1054, "Unknown column 'ai_tickets.customer_name' in 'field list'")
[22/Feb/2020 09:00:06] DEBUG [/home/thanhtran/workspace/python/env/movie/lib/python3.5/site-packages/django/db/backends/base/schema.py:101] ALTER TABLE `ai_tickets` ADD COLUMN `customer_name` varchar(100) DEFAULT %s NOT NULL; (params [''])
[22/Feb/2020 09:00:06] DEBUG [/home/thanhtran/workspace/python/env/movie/lib/python3.5/site-packages/django/db/backends/base/schema.py:101] ALTER TABLE `ai_tickets` ALTER COLUMN `customer_name` DROP DEFAULT; (params [])
[22/Feb/2020 09:21:16] ERROR [/home/thanhtran/workspace/python/env/movie/lib/python3.5/site-packages/django/core/handlers/base.py:284] Internal Server Error: /room/2
Traceback (most recent call last):
  File "/home/thanhtran/workspace/python/env/movie/lib/python3.5/site-packages/django/core/handlers/base.py", line 149, in get_response
    response = self.process_exception_by_middleware(e, request)
  File "/home/thanhtran/workspace/python/env/movie/lib/python3.5/site-packages/django/core/handlers/base.py", line 147, in get_response
    response = wrapped_callback(request, *callback_args, **callback_kwargs)
  File "/home/thanhtran/workspace/python/env/movie/lib/python3.5/site-packages/django/views/decorators/csrf.py", line 58, in wrapped_view
    return view_func(*args, **kwargs)
  File "/home/thanhtran/workspace/python/env/movie/lib/python3.5/site-packages/rest_framework/viewsets.py", line 87, in view
    return self.dispatch(request, *args, **kwargs)
  File "/home/thanhtran/workspace/python/env/movie/lib/python3.5/site-packages/rest_framework/views.py", line 466, in dispatch
    response = self.handle_exception(exc)
  File "/home/thanhtran/workspace/python/env/movie/lib/python3.5/site-packages/rest_framework/views.py", line 463, in dispatch
    response = handler(request, *args, **kwargs)
  File "/home/thanhtran/workspace/python/movie/core/views/room.py", line 72, in delete
    raise ex
  File "/home/thanhtran/workspace/python/movie/core/views/room.py", line 65, in delete
    room_in_used = RoomBookingService.room_is_in_used(room.id)
TypeError: room_is_in_used() takes 1 positional argument but 2 were given
[22/Feb/2020 09:22:13] ERROR [/home/thanhtran/workspace/python/env/movie/lib/python3.5/site-packages/django/core/handlers/base.py:284] Internal Server Error: /room/2
Traceback (most recent call last):
  File "/home/thanhtran/workspace/python/env/movie/lib/python3.5/site-packages/django/core/handlers/base.py", line 149, in get_response
    response = self.process_exception_by_middleware(e, request)
  File "/home/thanhtran/workspace/python/env/movie/lib/python3.5/site-packages/django/core/handlers/base.py", line 147, in get_response
    response = wrapped_callback(request, *callback_args, **callback_kwargs)
  File "/home/thanhtran/workspace/python/env/movie/lib/python3.5/site-packages/django/views/decorators/csrf.py", line 58, in wrapped_view
    return view_func(*args, **kwargs)
  File "/home/thanhtran/workspace/python/env/movie/lib/python3.5/site-packages/rest_framework/viewsets.py", line 87, in view
    return self.dispatch(request, *args, **kwargs)
  File "/home/thanhtran/workspace/python/env/movie/lib/python3.5/site-packages/rest_framework/views.py", line 466, in dispatch
    response = self.handle_exception(exc)
  File "/home/thanhtran/workspace/python/env/movie/lib/python3.5/site-packages/rest_framework/views.py", line 463, in dispatch
    response = handler(request, *args, **kwargs)
  File "/home/thanhtran/workspace/python/movie/core/views/room.py", line 72, in delete
    raise ex
  File "/home/thanhtran/workspace/python/movie/core/views/room.py", line 65, in delete
    room_in_used = RoomBookingService.room_is_in_used(room.id)
  File "/home/thanhtran/workspace/python/movie/core/services/room_booking.py", line 17, in room_is_in_used
    return RoomBooking.objects.get_all_room_booking(room_id=room_id, incoming_booking=True)
  File "/home/thanhtran/workspace/python/movie/core/managers/room_booking.py", line 15, in get_all_room_booking
    today_start_date = datetime.datetime.now()
AttributeError: type object 'datetime.datetime' has no attribute 'datetime'
[22/Feb/2020 09:25:48] ERROR [/home/thanhtran/workspace/python/env/movie/lib/python3.5/site-packages/django/core/handlers/base.py:284] Internal Server Error: /room/2
Traceback (most recent call last):
  File "/home/thanhtran/workspace/python/env/movie/lib/python3.5/site-packages/django/core/handlers/base.py", line 149, in get_response
    response = self.process_exception_by_middleware(e, request)
  File "/home/thanhtran/workspace/python/env/movie/lib/python3.5/site-packages/django/core/handlers/base.py", line 147, in get_response
    response = wrapped_callback(request, *callback_args, **callback_kwargs)
  File "/home/thanhtran/workspace/python/env/movie/lib/python3.5/site-packages/django/views/decorators/csrf.py", line 58, in wrapped_view
    return view_func(*args, **kwargs)
  File "/home/thanhtran/workspace/python/env/movie/lib/python3.5/site-packages/rest_framework/viewsets.py", line 87, in view
    return self.dispatch(request, *args, **kwargs)
  File "/home/thanhtran/workspace/python/env/movie/lib/python3.5/site-packages/rest_framework/views.py", line 466, in dispatch
    response = self.handle_exception(exc)
  File "/home/thanhtran/workspace/python/env/movie/lib/python3.5/site-packages/rest_framework/views.py", line 463, in dispatch
    response = handler(request, *args, **kwargs)
  File "/home/thanhtran/workspace/python/movie/core/views/room.py", line 72, in delete
    raise ex
  File "/home/thanhtran/workspace/python/movie/core/views/room.py", line 65, in delete
    room_in_used = RoomBookingService.room_is_in_used(room.id)
  File "/home/thanhtran/workspace/python/movie/core/services/room_booking.py", line 17, in room_is_in_used
    return RoomBooking.objects.get_all_room_booking(room_id=room_id, incoming_booking=True)
  File "/home/thanhtran/workspace/python/movie/core/managers/room_booking.py", line 17, in get_all_room_booking
    return self.filter(room_id=room_id, booked_at__ge=today_start_date)
  File "/home/thanhtran/workspace/python/env/movie/lib/python3.5/site-packages/django/db/models/manager.py", line 122, in manager_method
    return getattr(self.get_queryset(), name)(*args, **kwargs)
  File "/home/thanhtran/workspace/python/env/movie/lib/python3.5/site-packages/django/db/models/query.py", line 790, in filter
    return self._filter_or_exclude(False, *args, **kwargs)
  File "/home/thanhtran/workspace/python/env/movie/lib/python3.5/site-packages/django/db/models/query.py", line 808, in _filter_or_exclude
    clone.query.add_q(Q(*args, **kwargs))
  File "/home/thanhtran/workspace/python/env/movie/lib/python3.5/site-packages/django/db/models/sql/query.py", line 1243, in add_q
    clause, _ = self._add_q(q_object, self.used_aliases)
  File "/home/thanhtran/workspace/python/env/movie/lib/python3.5/site-packages/django/db/models/sql/query.py", line 1269, in _add_q
    allow_joins=allow_joins, split_subq=split_subq,
  File "/home/thanhtran/workspace/python/env/movie/lib/python3.5/site-packages/django/db/models/sql/query.py", line 1203, in build_filter
    condition = self.build_lookup(lookups, col, value)
  File "/home/thanhtran/workspace/python/env/movie/lib/python3.5/site-packages/django/db/models/sql/query.py", line 1097, in build_lookup
    lhs = self.try_transform(lhs, name, lookups)
  File "/home/thanhtran/workspace/python/env/movie/lib/python3.5/site-packages/django/db/models/sql/query.py", line 1115, in try_transform
    (name, lhs.output_field.__class__.__name__))
django.core.exceptions.FieldError: Unsupported lookup 'ge' for DateTimeField or join on the field not permitted.
[22/Feb/2020 09:33:10] ERROR [/home/thanhtran/workspace/python/env/movie/lib/python3.5/site-packages/django/core/handlers/base.py:284] Internal Server Error: /room/2
Traceback (most recent call last):
  File "/home/thanhtran/workspace/python/env/movie/lib/python3.5/site-packages/django/core/handlers/base.py", line 149, in get_response
    response = self.process_exception_by_middleware(e, request)
  File "/home/thanhtran/workspace/python/env/movie/lib/python3.5/site-packages/django/core/handlers/base.py", line 147, in get_response
    response = wrapped_callback(request, *callback_args, **callback_kwargs)
  File "/home/thanhtran/workspace/python/env/movie/lib/python3.5/site-packages/django/views/decorators/csrf.py", line 58, in wrapped_view
    return view_func(*args, **kwargs)
  File "/home/thanhtran/workspace/python/env/movie/lib/python3.5/site-packages/rest_framework/viewsets.py", line 87, in view
    return self.dispatch(request, *args, **kwargs)
  File "/home/thanhtran/workspace/python/env/movie/lib/python3.5/site-packages/rest_framework/views.py", line 466, in dispatch
    response = self.handle_exception(exc)
  File "/home/thanhtran/workspace/python/env/movie/lib/python3.5/site-packages/rest_framework/views.py", line 463, in dispatch
    response = handler(request, *args, **kwargs)
  File "/home/thanhtran/workspace/python/movie/core/views/room.py", line 72, in delete
    raise ex
  File "/home/thanhtran/workspace/python/movie/core/views/room.py", line 67, in delete
    raise Response('Room is already in used', status=status.HTTP_400_BAD_REQUEST)
TypeError: exceptions must derive from BaseException
[22/Feb/2020 09:35:11] ERROR [/home/thanhtran/workspace/python/env/movie/lib/python3.5/site-packages/django/core/handlers/base.py:284] Internal Server Error: /room/2
Traceback (most recent call last):
  File "/home/thanhtran/workspace/python/env/movie/lib/python3.5/site-packages/django/core/handlers/base.py", line 149, in get_response
    response = self.process_exception_by_middleware(e, request)
  File "/home/thanhtran/workspace/python/env/movie/lib/python3.5/site-packages/django/core/handlers/base.py", line 147, in get_response
    response = wrapped_callback(request, *callback_args, **callback_kwargs)
  File "/home/thanhtran/workspace/python/env/movie/lib/python3.5/site-packages/django/views/decorators/csrf.py", line 58, in wrapped_view
    return view_func(*args, **kwargs)
  File "/home/thanhtran/workspace/python/env/movie/lib/python3.5/site-packages/rest_framework/viewsets.py", line 87, in view
    return self.dispatch(request, *args, **kwargs)
  File "/home/thanhtran/workspace/python/env/movie/lib/python3.5/site-packages/rest_framework/views.py", line 466, in dispatch
    response = self.handle_exception(exc)
  File "/home/thanhtran/workspace/python/env/movie/lib/python3.5/site-packages/rest_framework/views.py", line 463, in dispatch
    response = handler(request, *args, **kwargs)
  File "/home/thanhtran/workspace/python/movie/core/views/room.py", line 72, in delete
    raise ex
  File "/home/thanhtran/workspace/python/movie/core/views/room.py", line 67, in delete
    raise Response({'error': 'Room is already in used'}, status=status.HTTP_400_BAD_REQUEST)
TypeError: exceptions must derive from BaseException
[22/Feb/2020 09:35:12] ERROR [/home/thanhtran/workspace/python/env/movie/lib/python3.5/site-packages/django/core/handlers/base.py:284] Internal Server Error: /room/2
Traceback (most recent call last):
  File "/home/thanhtran/workspace/python/env/movie/lib/python3.5/site-packages/django/core/handlers/base.py", line 149, in get_response
    response = self.process_exception_by_middleware(e, request)
  File "/home/thanhtran/workspace/python/env/movie/lib/python3.5/site-packages/django/core/handlers/base.py", line 147, in get_response
    response = wrapped_callback(request, *callback_args, **callback_kwargs)
  File "/home/thanhtran/workspace/python/env/movie/lib/python3.5/site-packages/django/views/decorators/csrf.py", line 58, in wrapped_view
    return view_func(*args, **kwargs)
  File "/home/thanhtran/workspace/python/env/movie/lib/python3.5/site-packages/rest_framework/viewsets.py", line 87, in view
    return self.dispatch(request, *args, **kwargs)
  File "/home/thanhtran/workspace/python/env/movie/lib/python3.5/site-packages/rest_framework/views.py", line 466, in dispatch
    response = self.handle_exception(exc)
  File "/home/thanhtran/workspace/python/env/movie/lib/python3.5/site-packages/rest_framework/views.py", line 463, in dispatch
    response = handler(request, *args, **kwargs)
  File "/home/thanhtran/workspace/python/movie/core/views/room.py", line 72, in delete
    raise ex
  File "/home/thanhtran/workspace/python/movie/core/views/room.py", line 67, in delete
    raise Response({'error': 'Room is already in used'}, status=status.HTTP_400_BAD_REQUEST)
TypeError: exceptions must derive from BaseException
[22/Feb/2020 09:35:13] ERROR [/home/thanhtran/workspace/python/env/movie/lib/python3.5/site-packages/django/core/handlers/base.py:284] Internal Server Error: /room/2
Traceback (most recent call last):
  File "/home/thanhtran/workspace/python/env/movie/lib/python3.5/site-packages/django/core/handlers/base.py", line 149, in get_response
    response = self.process_exception_by_middleware(e, request)
  File "/home/thanhtran/workspace/python/env/movie/lib/python3.5/site-packages/django/core/handlers/base.py", line 147, in get_response
    response = wrapped_callback(request, *callback_args, **callback_kwargs)
  File "/home/thanhtran/workspace/python/env/movie/lib/python3.5/site-packages/django/views/decorators/csrf.py", line 58, in wrapped_view
    return view_func(*args, **kwargs)
  File "/home/thanhtran/workspace/python/env/movie/lib/python3.5/site-packages/rest_framework/viewsets.py", line 87, in view
    return self.dispatch(request, *args, **kwargs)
  File "/home/thanhtran/workspace/python/env/movie/lib/python3.5/site-packages/rest_framework/views.py", line 466, in dispatch
    response = self.handle_exception(exc)
  File "/home/thanhtran/workspace/python/env/movie/lib/python3.5/site-packages/rest_framework/views.py", line 463, in dispatch
    response = handler(request, *args, **kwargs)
  File "/home/thanhtran/workspace/python/movie/core/views/room.py", line 72, in delete
    raise ex
  File "/home/thanhtran/workspace/python/movie/core/views/room.py", line 67, in delete
    raise Response({'error': 'Room is already in used'}, status=status.HTTP_400_BAD_REQUEST)
TypeError: exceptions must derive from BaseException
[22/Feb/2020 09:52:18] ERROR [/home/thanhtran/workspace/python/env/movie/lib/python3.5/site-packages/django/core/handlers/base.py:284] Internal Server Error: /ticket
Traceback (most recent call last):
  File "/home/thanhtran/workspace/python/env/movie/lib/python3.5/site-packages/django/core/handlers/base.py", line 149, in get_response
    response = self.process_exception_by_middleware(e, request)
  File "/home/thanhtran/workspace/python/env/movie/lib/python3.5/site-packages/django/core/handlers/base.py", line 147, in get_response
    response = wrapped_callback(request, *callback_args, **callback_kwargs)
  File "/home/thanhtran/workspace/python/env/movie/lib/python3.5/site-packages/django/views/decorators/csrf.py", line 58, in wrapped_view
    return view_func(*args, **kwargs)
  File "/home/thanhtran/workspace/python/env/movie/lib/python3.5/site-packages/rest_framework/viewsets.py", line 87, in view
    return self.dispatch(request, *args, **kwargs)
  File "/home/thanhtran/workspace/python/env/movie/lib/python3.5/site-packages/rest_framework/views.py", line 466, in dispatch
    response = self.handle_exception(exc)
  File "/home/thanhtran/workspace/python/env/movie/lib/python3.5/site-packages/rest_framework/views.py", line 463, in dispatch
    response = handler(request, *args, **kwargs)
  File "/home/thanhtran/workspace/python/movie/core/views/ticket.py", line 46, in create
    raise ex
  File "/home/thanhtran/workspace/python/movie/core/views/ticket.py", line 41, in create
    if serializer.is_valid(raise_exception=True):
  File "/home/thanhtran/workspace/python/env/movie/lib/python3.5/site-packages/rest_framework/serializers.py", line 213, in is_valid
    self._validated_data = self.run_validation(self.initial_data)
  File "/home/thanhtran/workspace/python/env/movie/lib/python3.5/site-packages/rest_framework/serializers.py", line 410, in run_validation
    value = self.validate(value)
  File "/home/thanhtran/workspace/python/movie/core/serializers/ticket.py", line 31, in validate
    raise Exception()
Exception
[22/Feb/2020 09:52:49] ERROR [/home/thanhtran/workspace/python/env/movie/lib/python3.5/site-packages/django/core/handlers/base.py:284] Internal Server Error: /ticket
Traceback (most recent call last):
  File "/home/thanhtran/workspace/python/env/movie/lib/python3.5/site-packages/django/core/handlers/base.py", line 149, in get_response
    response = self.process_exception_by_middleware(e, request)
  File "/home/thanhtran/workspace/python/env/movie/lib/python3.5/site-packages/django/core/handlers/base.py", line 147, in get_response
    response = wrapped_callback(request, *callback_args, **callback_kwargs)
  File "/home/thanhtran/workspace/python/env/movie/lib/python3.5/site-packages/django/views/decorators/csrf.py", line 58, in wrapped_view
    return view_func(*args, **kwargs)
  File "/home/thanhtran/workspace/python/env/movie/lib/python3.5/site-packages/rest_framework/viewsets.py", line 87, in view
    return self.dispatch(request, *args, **kwargs)
  File "/home/thanhtran/workspace/python/env/movie/lib/python3.5/site-packages/rest_framework/views.py", line 466, in dispatch
    response = self.handle_exception(exc)
  File "/home/thanhtran/workspace/python/env/movie/lib/python3.5/site-packages/rest_framework/views.py", line 463, in dispatch
    response = handler(request, *args, **kwargs)
  File "/home/thanhtran/workspace/python/movie/core/views/ticket.py", line 46, in create
    raise ex
  File "/home/thanhtran/workspace/python/movie/core/views/ticket.py", line 41, in create
    if serializer.is_valid(raise_exception=True):
  File "/home/thanhtran/workspace/python/env/movie/lib/python3.5/site-packages/rest_framework/serializers.py", line 213, in is_valid
    self._validated_data = self.run_validation(self.initial_data)
  File "/home/thanhtran/workspace/python/env/movie/lib/python3.5/site-packages/rest_framework/serializers.py", line 410, in run_validation
    value = self.validate(value)
  File "/home/thanhtran/workspace/python/movie/core/serializers/ticket.py", line 31, in validate
    raise Exception('test')
Exception: test
[22/Feb/2020 09:52:52] ERROR [/home/thanhtran/workspace/python/env/movie/lib/python3.5/site-packages/django/core/handlers/base.py:284] Internal Server Error: /ticket
Traceback (most recent call last):
  File "/home/thanhtran/workspace/python/env/movie/lib/python3.5/site-packages/django/core/handlers/base.py", line 149, in get_response
    response = self.process_exception_by_middleware(e, request)
  File "/home/thanhtran/workspace/python/env/movie/lib/python3.5/site-packages/django/core/handlers/base.py", line 147, in get_response
    response = wrapped_callback(request, *callback_args, **callback_kwargs)
  File "/home/thanhtran/workspace/python/env/movie/lib/python3.5/site-packages/django/views/decorators/csrf.py", line 58, in wrapped_view
    return view_func(*args, **kwargs)
  File "/home/thanhtran/workspace/python/env/movie/lib/python3.5/site-packages/rest_framework/viewsets.py", line 87, in view
    return self.dispatch(request, *args, **kwargs)
  File "/home/thanhtran/workspace/python/env/movie/lib/python3.5/site-packages/rest_framework/views.py", line 466, in dispatch
    response = self.handle_exception(exc)
  File "/home/thanhtran/workspace/python/env/movie/lib/python3.5/site-packages/rest_framework/views.py", line 463, in dispatch
    response = handler(request, *args, **kwargs)
  File "/home/thanhtran/workspace/python/movie/core/views/ticket.py", line 46, in create
    raise ex
  File "/home/thanhtran/workspace/python/movie/core/views/ticket.py", line 41, in create
    if serializer.is_valid(raise_exception=True):
  File "/home/thanhtran/workspace/python/env/movie/lib/python3.5/site-packages/rest_framework/serializers.py", line 213, in is_valid
    self._validated_data = self.run_validation(self.initial_data)
  File "/home/thanhtran/workspace/python/env/movie/lib/python3.5/site-packages/rest_framework/serializers.py", line 410, in run_validation
    value = self.validate(value)
  File "/home/thanhtran/workspace/python/movie/core/serializers/ticket.py", line 31, in validate
    raise Exception('test')
Exception: test
[22/Feb/2020 09:55:44] ERROR [/home/thanhtran/workspace/python/env/movie/lib/python3.5/site-packages/django/core/handlers/base.py:284] Internal Server Error: /ticket
Traceback (most recent call last):
  File "/home/thanhtran/workspace/python/env/movie/lib/python3.5/site-packages/django/core/handlers/base.py", line 149, in get_response
    response = self.process_exception_by_middleware(e, request)
  File "/home/thanhtran/workspace/python/env/movie/lib/python3.5/site-packages/django/core/handlers/base.py", line 147, in get_response
    response = wrapped_callback(request, *callback_args, **callback_kwargs)
  File "/home/thanhtran/workspace/python/env/movie/lib/python3.5/site-packages/django/views/decorators/csrf.py", line 58, in wrapped_view
    return view_func(*args, **kwargs)
  File "/home/thanhtran/workspace/python/env/movie/lib/python3.5/site-packages/rest_framework/viewsets.py", line 87, in view
    return self.dispatch(request, *args, **kwargs)
  File "/home/thanhtran/workspace/python/env/movie/lib/python3.5/site-packages/rest_framework/views.py", line 466, in dispatch
    response = self.handle_exception(exc)
  File "/home/thanhtran/workspace/python/env/movie/lib/python3.5/site-packages/rest_framework/views.py", line 463, in dispatch
    response = handler(request, *args, **kwargs)
  File "/home/thanhtran/workspace/python/movie/core/views/ticket.py", line 46, in create
    raise ex
  File "/home/thanhtran/workspace/python/movie/core/views/ticket.py", line 41, in create
    if serializer.is_valid(raise_exception=True):
  File "/home/thanhtran/workspace/python/env/movie/lib/python3.5/site-packages/rest_framework/serializers.py", line 213, in is_valid
    self._validated_data = self.run_validation(self.initial_data)
  File "/home/thanhtran/workspace/python/env/movie/lib/python3.5/site-packages/rest_framework/serializers.py", line 410, in run_validation
    value = self.validate(value)
  File "/home/thanhtran/workspace/python/movie/core/serializers/ticket.py", line 31, in validate
    raise Exception("The seat number is already booked!")
Exception: The seat number is already booked!
[22/Feb/2020 10:47:21] ERROR [/home/thanhtran/workspace/python/env/movie/lib/python3.5/site-packages/django/core/handlers/base.py:284] Internal Server Error: /room_booking
Traceback (most recent call last):
  File "/home/thanhtran/workspace/python/env/movie/lib/python3.5/site-packages/django/core/handlers/base.py", line 149, in get_response
    response = self.process_exception_by_middleware(e, request)
  File "/home/thanhtran/workspace/python/env/movie/lib/python3.5/site-packages/django/core/handlers/base.py", line 147, in get_response
    response = wrapped_callback(request, *callback_args, **callback_kwargs)
  File "/home/thanhtran/workspace/python/env/movie/lib/python3.5/site-packages/django/views/decorators/csrf.py", line 58, in wrapped_view
    return view_func(*args, **kwargs)
  File "/home/thanhtran/workspace/python/env/movie/lib/python3.5/site-packages/rest_framework/viewsets.py", line 87, in view
    return self.dispatch(request, *args, **kwargs)
  File "/home/thanhtran/workspace/python/env/movie/lib/python3.5/site-packages/rest_framework/views.py", line 466, in dispatch
    response = self.handle_exception(exc)
  File "/home/thanhtran/workspace/python/env/movie/lib/python3.5/site-packages/rest_framework/views.py", line 463, in dispatch
    response = handler(request, *args, **kwargs)
  File "/home/thanhtran/workspace/python/movie/core/views/room_booking.py", line 33, in create
    raise ex
  File "/home/thanhtran/workspace/python/movie/core/views/room_booking.py", line 28, in create
    if serializer.is_valid(raise_exception=True):
  File "/home/thanhtran/workspace/python/env/movie/lib/python3.5/site-packages/rest_framework/serializers.py", line 213, in is_valid
    self._validated_data = self.run_validation(self.initial_data)
  File "/home/thanhtran/workspace/python/env/movie/lib/python3.5/site-packages/rest_framework/serializers.py", line 410, in run_validation
    value = self.validate(value)
  File "/home/thanhtran/workspace/python/movie/core/serializers/room_booking.py", line 40, in validate
    booked_at = datetime(booked_at)
TypeError: an integer is required (got type str)
[22/Feb/2020 11:00:10] ERROR [/home/thanhtran/workspace/python/env/movie/lib/python3.5/site-packages/django/core/handlers/base.py:284] Internal Server Error: /room_booking
Traceback (most recent call last):
  File "/home/thanhtran/workspace/python/env/movie/lib/python3.5/site-packages/django/core/handlers/base.py", line 149, in get_response
    response = self.process_exception_by_middleware(e, request)
  File "/home/thanhtran/workspace/python/env/movie/lib/python3.5/site-packages/django/core/handlers/base.py", line 147, in get_response
    response = wrapped_callback(request, *callback_args, **callback_kwargs)
  File "/home/thanhtran/workspace/python/env/movie/lib/python3.5/site-packages/django/views/decorators/csrf.py", line 58, in wrapped_view
    return view_func(*args, **kwargs)
  File "/home/thanhtran/workspace/python/env/movie/lib/python3.5/site-packages/rest_framework/viewsets.py", line 87, in view
    return self.dispatch(request, *args, **kwargs)
  File "/home/thanhtran/workspace/python/env/movie/lib/python3.5/site-packages/rest_framework/views.py", line 466, in dispatch
    response = self.handle_exception(exc)
  File "/home/thanhtran/workspace/python/env/movie/lib/python3.5/site-packages/rest_framework/views.py", line 463, in dispatch
    response = handler(request, *args, **kwargs)
  File "/home/thanhtran/workspace/python/movie/core/views/room_booking.py", line 33, in create
    raise ex
  File "/home/thanhtran/workspace/python/movie/core/views/room_booking.py", line 28, in create
    if serializer.is_valid(raise_exception=True):
  File "/home/thanhtran/workspace/python/env/movie/lib/python3.5/site-packages/rest_framework/serializers.py", line 213, in is_valid
    self._validated_data = self.run_validation(self.initial_data)
  File "/home/thanhtran/workspace/python/env/movie/lib/python3.5/site-packages/rest_framework/serializers.py", line 410, in run_validation
    value = self.validate(value)
  File "/home/thanhtran/workspace/python/movie/core/serializers/room_booking.py", line 42, in validate
    booked_at.setHours(hour_start)
AttributeError: 'datetime.datetime' object has no attribute 'setHours'
[22/Feb/2020 11:12:07] ERROR [/home/thanhtran/workspace/python/env/movie/lib/python3.5/site-packages/django/core/handlers/base.py:284] Internal Server Error: /movie
Traceback (most recent call last):
  File "/home/thanhtran/workspace/python/env/movie/lib/python3.5/site-packages/django/core/handlers/base.py", line 149, in get_response
    response = self.process_exception_by_middleware(e, request)
  File "/home/thanhtran/workspace/python/env/movie/lib/python3.5/site-packages/django/core/handlers/base.py", line 147, in get_response
    response = wrapped_callback(request, *callback_args, **callback_kwargs)
  File "/home/thanhtran/workspace/python/env/movie/lib/python3.5/site-packages/django/views/decorators/csrf.py", line 58, in wrapped_view
    return view_func(*args, **kwargs)
  File "/home/thanhtran/workspace/python/env/movie/lib/python3.5/site-packages/rest_framework/viewsets.py", line 87, in view
    return self.dispatch(request, *args, **kwargs)
  File "/home/thanhtran/workspace/python/env/movie/lib/python3.5/site-packages/rest_framework/views.py", line 466, in dispatch
    response = self.handle_exception(exc)
  File "/home/thanhtran/workspace/python/env/movie/lib/python3.5/site-packages/rest_framework/views.py", line 463, in dispatch
    response = handler(request, *args, **kwargs)
  File "/home/thanhtran/workspace/python/movie/core/views/movie.py", line 46, in create
    raise ex
  File "/home/thanhtran/workspace/python/movie/core/views/movie.py", line 41, in create
    if serializer.is_valid(raise_exception=True):
  File "/home/thanhtran/workspace/python/env/movie/lib/python3.5/site-packages/rest_framework/serializers.py", line 213, in is_valid
    self._validated_data = self.run_validation(self.initial_data)
  File "/home/thanhtran/workspace/python/env/movie/lib/python3.5/site-packages/rest_framework/serializers.py", line 410, in run_validation
    value = self.validate(value)
  File "/home/thanhtran/workspace/python/movie/core/serializers/movie.py", line 32, in validate
    raise Exception("Start at is invalid!")
Exception: Start at is invalid!
[22/Feb/2020 11:12:27] ERROR [/home/thanhtran/workspace/python/env/movie/lib/python3.5/site-packages/django/core/handlers/base.py:284] Internal Server Error: /movie
Traceback (most recent call last):
  File "/home/thanhtran/workspace/python/env/movie/lib/python3.5/site-packages/django/core/handlers/base.py", line 149, in get_response
    response = self.process_exception_by_middleware(e, request)
  File "/home/thanhtran/workspace/python/env/movie/lib/python3.5/site-packages/django/core/handlers/base.py", line 147, in get_response
    response = wrapped_callback(request, *callback_args, **callback_kwargs)
  File "/home/thanhtran/workspace/python/env/movie/lib/python3.5/site-packages/django/views/decorators/csrf.py", line 58, in wrapped_view
    return view_func(*args, **kwargs)
  File "/home/thanhtran/workspace/python/env/movie/lib/python3.5/site-packages/rest_framework/viewsets.py", line 87, in view
    return self.dispatch(request, *args, **kwargs)
  File "/home/thanhtran/workspace/python/env/movie/lib/python3.5/site-packages/rest_framework/views.py", line 466, in dispatch
    response = self.handle_exception(exc)
  File "/home/thanhtran/workspace/python/env/movie/lib/python3.5/site-packages/rest_framework/views.py", line 463, in dispatch
    response = handler(request, *args, **kwargs)
  File "/home/thanhtran/workspace/python/movie/core/views/movie.py", line 46, in create
    raise ex
  File "/home/thanhtran/workspace/python/movie/core/views/movie.py", line 41, in create
    if serializer.is_valid(raise_exception=True):
  File "/home/thanhtran/workspace/python/env/movie/lib/python3.5/site-packages/rest_framework/serializers.py", line 213, in is_valid
    self._validated_data = self.run_validation(self.initial_data)
  File "/home/thanhtran/workspace/python/env/movie/lib/python3.5/site-packages/rest_framework/serializers.py", line 410, in run_validation
    value = self.validate(value)
  File "/home/thanhtran/workspace/python/movie/core/serializers/movie.py", line 32, in validate
    raise Exception("Start at is invalid!")
Exception: Start at is invalid!
